Workbook

Sheet Pivot Table
A1: Years (Date) | B1: (All)
A2: Quarters (Date) | B2: (All) | D2: Sum of TotalPrice | G2: Product | H2: Sum of TotalPrice
A3: Date | B3: (All) | D3: 1264762 | G3: Chair | H3: 195620.11 | J3: Years (Date) | K3: Quarters (Date) | L3: Months (Date) | M3: Product | N3: Date | O3: Sum of TotalPrice
G4: Printer | H4: 195612.61 | J4: 2023 | K4: Qtr1 | L4: Jan | O4: 56685.75
A5: Months (Date) | B5: Sum of TotalPrice | D5: =GETPIVOTDATA("TotalPrice",$D$2) -> 1264762 | G5: Laptop | H5: 192126.56 | L5: Feb | O5: 40117.66
A6: Jan | B6: 124313.23 | G6: Tablet | H6: 186568.95 | L6: Mar | O6: 48609.37
A7: Feb | B7: 112344.78 | D7: Sum of UnitPrice | G7: Monitor | H7: 175651.41 | K7: Qtr1 Total | O7: 145412.78
A8: Mar | B8: 123840.93 | D8: 427695.3 | G8: Desk | H8: 167459.93 | K8: Qtr2 | L8: Apr | O8: 27751.71
A9: Apr | B9: 109186.05 | D9: =GETPIVOTDATA("UnitPrice",$D$7) -> 427695.3 | G9: Phone | H9: 151722.39 | L9: May | O9: 63836.84
A10: May | B10: 135142.59 | L10: Jun | O10: 49500.19
A11: Jun | B11: 170616.13 | D11: Sum of ItemsInCart | K11: Qtr2 Total | O11: 141088.74
A12: Jul | B12: 85784.64 | D12: 6582 | K12: Qtr3 | O12: 126699.47
A13: Aug | B13: 86343.21 | D13: =GETPIVOTDATA("ItemsInCart",$D$11) -> 6582 | K13: Qtr4 | O13: 139442.25
A14: Sep | B14: 69321.65 | G14: Quantity | H14: Sum of TotalPrice | J14: 2023 Total | O14: 552643.24
A15: Oct | B15: 89834.82 | D15: Count of CustomerID | G15: 5 | H15: 379936.85 | J15: 2024 | O15: 480235.87
A16: Nov | B16: 75493.43 | D16: 1200 | G16: 4 | H16: 368090.96 | J16: 2025 | K16: Qtr1 | L16: Jan | O16: 29099.4
A17: Dec | B17: 82540.5 | D17: =GETPIVOTDATA("CustomerID",$D$15) -> 1200 | G17: 3 | H17: 261276.18 | L17: Feb | O17: 35317.55
A18: Grand Total | B18: 1264762 | G18: 2 | H18: 165729.68 | L18: Mar | O18: 39200.66
G19: 1 | H19: 89728.29 | K19: Qtr1 Total | O19: 103617.61
D20: Average of Quantity | K20: Qtr2 | L20: Apr | O20: 31821.2
D21: 2.9458333 | L21: May | O21: 43396.64
D22: =GETPIVOTDATA("Quantity",$D$20) -> 2.9458333 | L22: Jun | O22: 53047.4
G23: PaymentMethod | H23: Sum of TotalPrice | K23: Qtr2 Total | O23: 128265.24
G24: Credit Card | H24: 263847.63 | J24: 2025 Total | O24: 231882.85
C25: =G14 -> Quantity | D25: =H14 -> Sum of TotalPrice | G25: Online | H25: 262442.94
C26: =G15 -> 5 | D26: =H15 -> 379936.85 | G26: Cash | H26: 259786.29
C27: =G16 -> 4 | D27: =H16 -> 368090.96 | G27: Gift Card | H27: 246323.92
C28: =G17 -> 3 | D28: =H17 -> 261276.18 | G28: Debit Card | H28: 232361.18
C29: =G18 -> 2 | D29: =H18 -> 165729.68
C30: =G19 -> 1 | D30: =H19 -> 89728.29
G32: OrderStatus | H32: Sum of TotalPrice | J32: OrderStatus | K32: Count of OrderStatus
G33: Cancelled | H33: 276396.21 | J33: Cancelled | K33: 250
G34: Pending | H34: 256328.15 | J34: Delivered | K34: 231
G35: Shipped | H35: 246159.58 | J35: Pending | K35: 237
G36: Returned | H36: 243277.7 | J36: Returned | K36: 247
G37: Delivered | H37: 242600.32 | J37: Shipped | K37: 235
G41: ItemsInCart | H41: Sum of TotalPrice
G42: 6 | H42: 212718.75
G43: 5 | H43: 201617.19
G44: 8 | H44: 191982.26
...

Sheet Dashboard

Sheet Sheet1
A1: OrderID | B1: Date | C1: CustomerID | D1: Product | E1: Quantity | F1: UnitPrice | G1: ShippingAddress | H1: PaymentMethod | I1: OrderStatus | J1: TrackingNumber | K1: ItemsInCart | L1: CouponCode | M1: ReferralSource | N1: TotalPrice
A2: ORD200000 | B2: 44930 | C2: C72649 | D2: Monitor | E2: 5 | F2: 570.62 | G2: 928 Main St | H2: Debit Card | I2: Shipped | J2: TRK37947903 | K2: 7 | L2: SAVE10 | M2: Instagram | N2: 2853.1
A3: ORD200001 | B3: 45527 | C3: C75739 | D3: Phone | E3: 2 | F3: 151.35 | G3: 823 Main St | H3: Online | I3: Shipped | J3: TRK91186779 | K3: 3 | L3: SAVE10 | M3: Referral | N3: 302.7
A4: ORD200002 | B4: 45349 | C4: C81728 | D4: Tablet | E4: 5 | F4: 550.68 | G4: 512 Main St | H4: Credit Card | I4: Cancelled | J4: TRK42903982 | K4: 8 | L4: FREESHIP | M4: Email | N4: 2753.4
A5: ORD200003 | B5: 45214 | C5: C33540 | D5: Chair | E5: 1 | F5: 273.19 | G5: 275 Main St | H5: Debit Card | I5: Returned | J5: TRK62788070 | K5: 5 | L5: SAVE10 | M5: Facebook | N5: 273.19
A6: ORD200004 | B6: 45785 | C6: C81840 | D6: Printer | E6: 4 | F6: 626.01 | G6: 668 Main St | H6: Online | I6: Delivered | J6: TRK29241424 | K6: 8 | L6: SAVE10 | M6: Email | N6: 2504.04
A7: ORD200005 | B7: 45222 | C7: C37249 | D7: Phone | E7: 2 | F7: 245.86 | G7: 934 Main St | H7: Credit Card | I7: Shipped | J7: TRK72976927 | K7: 4 | L7: SAVE10 | M7: Instagram | N7: 491.72
A8: ORD200006 | B8: 45825 | C8: C83492 | D8: Laptop | E8: 1 | F8: 664.42 | G8: 986 Main St | H8: Gift Card | I8: Returned | J8: TRK96417362 | K8: 6 | L8: SAVE10 | M8: Facebook | N8: 664.42
A9: ORD200007 | B9: 45058 | C9: C41460 | D9: Monitor | E9: 5 | F9: 149.55 | G9: 706 Main St | H9: Cash | I9: Shipped | J9: TRK78809193 | K9: 9 | L9: FREESHIP | M9: Facebook | N9: 747.75
A10: ORD200008 | B10: 45749 | C10: C26817 | D10: Phone | E10: 2 | F10: 134.28 | G10: 904 Main St | H10: Gift Card | I10: Cancelled | J10: TRK61042692 | K10: 2 | L10: No Coupon | M10: Email | N10: 268.56
A11: ORD200009 | B11: 45251 | C11: C31946 | D11: Desk | E11: 4 | F11: 509.38 | G11: 102 Main St | H11: Credit Card | I11: Shipped | J11: TRK33478363 | K11: 6 | L11: SAVE10 | M11: Google | N11: 2037.52
A12: ORD200010 | B12: 45289 | C12: C43443 | D12: Tablet | E12: 5 | F12: 625.97 | G12: 333 Main St | H12: Credit Card | I12: Returned | J12: TRK98859248 | K12: 9 | L12: WINTER15 | M12: Instagram | N12: 3129.85
A13: ORD200011 | B13: 45339 | C13: C93861 | D13: Monitor | E13: 3 | F13: 49.14 | G13: 831 Main St | H13: Online | I13: Returned | J13: TRK48234646 | K13: 7 | L13: SAVE10 | M13: Email | N13: 147.42
... A1201: ORD201199 | B1201: 45088 | C1201: C57502 | D1201: Tablet | E1201: 4 | F1201: 560.58 | G1201: 201 Main St | H1201: Gift Card | I1201: Returned | J1201: TRK51116746 | K1201: 6 | L1201: SAVE10 | M1201: Referral | N1201: 2242.32
D1203: Mean | E1203: =AVERAGE($E$2:$E$1201) -> 2.9458333 | F1203: =AVERAGE($F$2:$F$1201) -> 356.41275 | K1203: =AVERAGE($K$2:$K$1201) -> 5.485 | N1203: =AVERAGE($N$2:$N$1201) -> 1053.9683
D1204: Median | E1204: =MEDIAN($E$2:$E$1203) -> 3 | F1204: =MEDIAN($F$2:$F$1201) -> 364.21 | K1204: =MEDIAN($K$2:$K$1203) -> 5 | N1204: =MEDIAN($N$2:$N$1201) -> 823.615
D1205: Count | E1205: =COUNT($E$2:$E$1201) -> 1200 | F1205: =COUNT($F$2:$F$1201) -> 1200 | K1205: =COUNT($K$2:$K$1201) -> 1200 | N1205: =COUNT($N$2:$N$1201) -> 1200
D1206: min | E1206: =MIN($E$2:$E$1201) -> 1 | F1206: =MIN($F$2:$F$1201) -> 11.39 | K1206: =MIN($K$2:$K$1201) -> 1 | N1206: =MIN($N$2:$N$1201) -> 11.39
D1207: max | E1207: =MAX($E$2:$E$1201) -> 5 | F1207: =MAX($F$2:$F$1201) -> 699.93 | K1207: =MAX($K$2:$K$1201) -> 10 | N1207: =MAX($N$2:$N$1201) -> 3456.4

Sheet Count, mean and median
A1: Column | B1: Count | C1: Mean | D1: Median | E1: Min | F1: Max | G1: Q1 | H1: Q3 | I1: IQR | J1: Upper limit | K1: Lower limit | L1: Outlier
A2: Quantity | B2: =Sheet1!E1205 -> 1200 | C2: =Sheet1!E1203 -> 2.9458333 | D2: =Sheet1!E1204 -> 3 | E2: =Sheet1!E1206 -> 1 | F2: =Sheet1!E1207 -> 5
A3: UnitPrice | B3: =Sheet1!F1205 -> 1200 | C3: =Sheet1!F1203 -> 356.41275 | D3: =Sheet1!F1204 -> 364.21 | E3: =Sheet1!F1206 -> 11.39 | F3: =Sheet1!F1207 -> 699.93
A4: ItemsInCart | B4: =Sheet1!K1205 -> 1200 | C4: =Sheet1!K1203 -> 5.485 | D4: =Sheet1!K1204 -> 5 | E4: =Sheet1!K1206 -> 1 | F4: =Sheet1!K1207 -> 10
A5: TotalPrice | B5: =Sheet1!N1205 -> 1200 | C5: =Sheet1!N1203 -> 1053.9683 | D5: =Sheet1!N1204 -> 823.615 | E5: =Sheet1!N1206 -> 11.39 | F5: =Sheet1!N1207 -> 3456.4 | G5: =_xlfn.QUARTILE.INC(Sheet1!N2:N1201,1) -> 410.52 | H5: =_xlfn.QUARTILE.INC(Sheet1!N2:N1201,3) -> 1578.475 | I5: =H5-G5 -> 1167.955 | J5: =H5+1.5*I5 -> 3330.4075 | K5: =G5-1.5*I5 -> -1341.4125 | L5: =COUNTIF(Sheet1!N2:N1201,">3330.41") -> 8
F13: ==QUARTILE.INC(N2:N1201,1)
